2025-09-01 21:34:43 | INFO     | root                      | configure_logging   :164  | Sistema de logging configurado correctamente
2025-09-01 21:34:43 | INFO     | root                      | configure_logging   :165  | Nivel de logging: INFO
2025-09-01 21:34:43 | INFO     | root                      | configure_logging   :167  | Logs de archivo habilitados en: logs
2025-09-01 21:34:43 | INFO     | root                      | configure_logging   :169  | Logs de consola habilitados
2025-09-01 21:34:51 | INFO     | ImageToExcelApp           | select_image        :506  | Imagen seleccionada: C:/Users/Javier/Downloads/WhatsApp Image 2025-08-21 at 14.01.47 - copia.jpeg
2025-09-01 21:34:55 | INFO     | ImageToExcelApp           | select_output_directory:535  | Directorio de salida seleccionado: C:/Users/Javier/Downloads
2025-09-01 21:34:56 | INFO     | ImageProcessor            | process_image       :98   | Iniciando procesamiento de imagen: C:/Users/Javier/Downloads/WhatsApp Image 2025-08-21 at 14.01.47 - copia.jpeg
2025-09-01 21:34:56 | INFO     | ImageToExcelApp           | on_processing_started:569  | Procesamiento iniciado
2025-09-01 21:34:56 | ERROR    | services.paddle_ocr       | shutdown            :372  | Error al cerrar motor OCR: 'PaddleOCREngine' object has no attribute '_ocr'
2025-09-01 21:34:56 | ERROR    | ImageProcessor            | process_image       :139  | Error durante el procesamiento: PaddleOCREngine.__init__() got an unexpected keyword argument 'language'
Traceback (most recent call last):
  File "C:\Users\Javier\Desktop\Proyectos\I2E\main.py", line 108, in process_image
    self._ocr_engine = PaddleOCREngine(
TypeError: PaddleOCREngine.__init__() got an unexpected keyword argument 'language'
2025-09-01 21:34:59 | ERROR    | ImageToExcelApp           | on_processing_error :595  | Error en conversión: Error durante el procesamiento: PaddleOCREngine.__init__() got an unexpected keyword argument 'language'
2025-09-01 21:49:13 | INFO     | root                      | configure_logging   :164  | Sistema de logging configurado correctamente
2025-09-01 21:49:13 | INFO     | root                      | configure_logging   :165  | Nivel de logging: INFO
2025-09-01 21:49:13 | INFO     | root                      | configure_logging   :167  | Logs de archivo habilitados en: logs
2025-09-01 21:49:13 | INFO     | root                      | configure_logging   :169  | Logs de consola habilitados
2025-09-01 21:49:19 | INFO     | ImageToExcelApp           | select_image        :506  | Imagen seleccionada: C:/Users/Javier/Downloads/WhatsApp Image 2025-08-21 at 14.01.47 - copia.jpeg
2025-09-01 21:49:23 | INFO     | ImageToExcelApp           | select_output_directory:535  | Directorio de salida seleccionado: C:/Users/Javier/Downloads
2025-09-01 21:49:24 | INFO     | ImageProcessor            | process_image       :98   | Iniciando procesamiento de imagen: C:/Users/Javier/Downloads/WhatsApp Image 2025-08-21 at 14.01.47 - copia.jpeg
2025-09-01 21:49:24 | INFO     | ImageToExcelApp           | on_processing_started:569  | Procesamiento iniciado
2025-09-01 21:49:24 | ERROR    | services.paddle_ocr       | shutdown            :372  | Error al cerrar motor OCR: 'PaddleOCREngine' object has no attribute '_ocr'
2025-09-01 21:49:24 | ERROR    | ImageProcessor            | process_image       :139  | Error durante el procesamiento: PaddleOCREngine.__init__() got an unexpected keyword argument 'language'
Traceback (most recent call last):
  File "C:\Users\Javier\Desktop\Proyectos\I2E\main.py", line 108, in process_image
    self._ocr_engine = PaddleOCREngine(
TypeError: PaddleOCREngine.__init__() got an unexpected keyword argument 'language'
2025-09-01 21:54:11 | ERROR    | ImageToExcelApp           | on_processing_error :595  | Error en conversión: Error durante el procesamiento: PaddleOCREngine.__init__() got an unexpected keyword argument 'language'
2025-09-01 21:54:21 | INFO     | root                      | configure_logging   :164  | Sistema de logging configurado correctamente
2025-09-01 21:54:21 | INFO     | root                      | configure_logging   :165  | Nivel de logging: INFO
2025-09-01 21:54:21 | INFO     | root                      | configure_logging   :167  | Logs de archivo habilitados en: logs
2025-09-01 21:54:21 | INFO     | root                      | configure_logging   :169  | Logs de consola habilitados
2025-09-01 21:54:25 | INFO     | ImageToExcelApp           | select_image        :494  | Imagen seleccionada: C:/Users/Javier/Downloads/WhatsApp Image 2025-08-21 at 14.01.47 - copia.jpeg
2025-09-01 21:54:30 | INFO     | ImageToExcelApp           | select_output_directory:523  | Directorio de salida seleccionado: C:/Users/Javier/Downloads
2025-09-01 21:54:31 | INFO     | ImageProcessor            | process_image       :79   | Iniciando procesamiento de imagen: C:/Users/Javier/Downloads/WhatsApp Image 2025-08-21 at 14.01.47 - copia.jpeg
2025-09-01 21:54:31 | INFO     | ImageToExcelApp           | on_processing_started:557  | Procesamiento iniciado
2025-09-01 21:54:31 | INFO     | services.paddle_ocr       | __init__            :73   | PaddleOCREngine inicializado con configuración: language=es, use_angle_cls=True, use_gpu=False
2025-09-01 21:54:31 | INFO     | ImageProcessor            | process_image       :98   | Ejecutando OCR en la imagen
2025-09-01 21:54:31 | INFO     | services.paddle_ocr       | _initialize_ocr     :85   | Inicializando motor PaddleOCR...
2025-09-01 21:54:31 | ERROR    | services.paddle_ocr       | _initialize_ocr     :118  | Error al inicializar motor PaddleOCR
Traceback (most recent call last):
  File "C:\Users\Javier\Desktop\Proyectos\I2E\services\paddle_ocr.py", line 111, in _initialize_ocr
    self._ocr = PaddleOCR(**ocr_params)
  File "C:\Users\Javier\Desktop\Proyectos\I2E\.venv\lib\site-packages\paddleocr\_pipelines\ocr.py", line 163, in __init__
    super().__init__(**base_params)
  File "C:\Users\Javier\Desktop\Proyectos\I2E\.venv\lib\site-packages\paddleocr\_pipelines\base.py", line 63, in __init__
    self._common_args = parse_common_args(
  File "C:\Users\Javier\Desktop\Proyectos\I2E\.venv\lib\site-packages\paddleocr\_common_args.py", line 43, in parse_common_args
    raise ValueError(f"Unknown argument: {name}")
ValueError: Unknown argument: cls_thresh
2025-09-01 21:54:31 | ERROR    | services.paddle_ocr       | extract_text        :174  | Error en extracción de texto para imagen: C:/Users/Javier/Downloads/WhatsApp Image 2025-08-21 at 14.01.47 - copia.jpeg
Traceback (most recent call last):
  File "C:\Users\Javier\Desktop\Proyectos\I2E\services\paddle_ocr.py", line 111, in _initialize_ocr
    self._ocr = PaddleOCR(**ocr_params)
  File "C:\Users\Javier\Desktop\Proyectos\I2E\.venv\lib\site-packages\paddleocr\_pipelines\ocr.py", line 163, in __init__
    super().__init__(**base_params)
  File "C:\Users\Javier\Desktop\Proyectos\I2E\.venv\lib\site-packages\paddleocr\_pipelines\base.py", line 63, in __init__
    self._common_args = parse_common_args(
  File "C:\Users\Javier\Desktop\Proyectos\I2E\.venv\lib\site-packages\paddleocr\_common_args.py", line 43, in parse_common_args
    raise ValueError(f"Unknown argument: {name}")
ValueError: Unknown argument: cls_thresh

The above exception was the direct cause of the following exception:

Traceback (most recent call last):
  File "C:\Users\Javier\Desktop\Proyectos\I2E\services\paddle_ocr.py", line 149, in extract_text
    self._initialize_ocr()
  File "C:\Users\Javier\Desktop\Proyectos\I2E\services\paddle_ocr.py", line 119, in _initialize_ocr
    raise RuntimeError(f"Fallo en la inicialización de PaddleOCR: {str(e)}") from e
RuntimeError: Fallo en la inicialización de PaddleOCR: Unknown argument: cls_thresh
2025-09-01 21:54:31 | ERROR    | ImageProcessor            | process_image       :122  | Error durante el procesamiento: Error en OCR: Fallo en la inicialización de PaddleOCR: Unknown argument: cls_thresh
Traceback (most recent call last):
  File "C:\Users\Javier\Desktop\Proyectos\I2E\services\paddle_ocr.py", line 111, in _initialize_ocr
    self._ocr = PaddleOCR(**ocr_params)
  File "C:\Users\Javier\Desktop\Proyectos\I2E\.venv\lib\site-packages\paddleocr\_pipelines\ocr.py", line 163, in __init__
    super().__init__(**base_params)
  File "C:\Users\Javier\Desktop\Proyectos\I2E\.venv\lib\site-packages\paddleocr\_pipelines\base.py", line 63, in __init__
    self._common_args = parse_common_args(
  File "C:\Users\Javier\Desktop\Proyectos\I2E\.venv\lib\site-packages\paddleocr\_common_args.py", line 43, in parse_common_args
    raise ValueError(f"Unknown argument: {name}")
ValueError: Unknown argument: cls_thresh

The above exception was the direct cause of the following exception:

Traceback (most recent call last):
  File "C:\Users\Javier\Desktop\Proyectos\I2E\services\paddle_ocr.py", line 149, in extract_text
    self._initialize_ocr()
  File "C:\Users\Javier\Desktop\Proyectos\I2E\services\paddle_ocr.py", line 119, in _initialize_ocr
    raise RuntimeError(f"Fallo en la inicialización de PaddleOCR: {str(e)}") from e
RuntimeError: Fallo en la inicialización de PaddleOCR: Unknown argument: cls_thresh

The above exception was the direct cause of the following exception:

Traceback (most recent call last):
  File "C:\Users\Javier\Desktop\Proyectos\I2E\main.py", line 99, in process_image
    ocr_result = self._ocr_engine.extract_text(image_path)
  File "C:\Users\Javier\Desktop\Proyectos\I2E\services\paddle_ocr.py", line 177, in extract_text
    raise RuntimeError(f"Error en OCR: {str(e)}") from e
RuntimeError: Error en OCR: Fallo en la inicialización de PaddleOCR: Unknown argument: cls_thresh
2025-09-01 21:54:34 | ERROR    | ImageToExcelApp           | on_processing_error :583  | Error en conversión: Error durante el procesamiento: Error en OCR: Fallo en la inicialización de PaddleOCR: Unknown argument: cls_thresh
2025-09-01 21:56:59 | INFO     | root                      | configure_logging   :164  | Sistema de logging configurado correctamente
2025-09-01 21:56:59 | INFO     | root                      | configure_logging   :165  | Nivel de logging: INFO
2025-09-01 21:56:59 | INFO     | root                      | configure_logging   :167  | Logs de archivo habilitados en: logs
2025-09-01 21:56:59 | INFO     | root                      | configure_logging   :169  | Logs de consola habilitados
2025-09-01 21:57:03 | INFO     | ImageToExcelApp           | select_image        :494  | Imagen seleccionada: C:/Users/Javier/Downloads/WhatsApp Image 2025-08-21 at 14.01.47 - copia.jpeg
2025-09-01 21:57:07 | INFO     | ImageToExcelApp           | select_output_directory:523  | Directorio de salida seleccionado: C:/Users/Javier/Downloads
2025-09-01 21:57:09 | INFO     | ImageProcessor            | process_image       :79   | Iniciando procesamiento de imagen: C:/Users/Javier/Downloads/WhatsApp Image 2025-08-21 at 14.01.47 - copia.jpeg
2025-09-01 21:57:09 | INFO     | ImageToExcelApp           | on_processing_started:557  | Procesamiento iniciado
2025-09-01 21:57:09 | INFO     | services.paddle_ocr       | __init__            :66   | PaddleOCREngine inicializado con configuración: language=es, use_angle_cls=True, use_gpu=False
2025-09-01 21:57:09 | INFO     | ImageProcessor            | process_image       :98   | Ejecutando OCR en la imagen
2025-09-01 21:57:09 | INFO     | services.paddle_ocr       | _initialize_ocr     :78   | Inicializando motor PaddleOCR...
2025-09-01 21:57:09 | ERROR    | services.paddle_ocr       | _initialize_ocr     :113  | Error al inicializar motor PaddleOCR
Traceback (most recent call last):
  File "C:\Users\Javier\Desktop\Proyectos\I2E\services\paddle_ocr.py", line 106, in _initialize_ocr
    self._ocr = PaddleOCR(**ocr_params)
  File "C:\Users\Javier\Desktop\Proyectos\I2E\.venv\lib\site-packages\paddleocr\_pipelines\ocr.py", line 163, in __init__
    super().__init__(**base_params)
  File "C:\Users\Javier\Desktop\Proyectos\I2E\.venv\lib\site-packages\paddleocr\_pipelines\base.py", line 63, in __init__
    self._common_args = parse_common_args(
  File "C:\Users\Javier\Desktop\Proyectos\I2E\.venv\lib\site-packages\paddleocr\_common_args.py", line 43, in parse_common_args
    raise ValueError(f"Unknown argument: {name}")
ValueError: Unknown argument: use_gpu
2025-09-01 21:57:09 | ERROR    | services.paddle_ocr       | extract_text        :169  | Error en extracción de texto para imagen: C:/Users/Javier/Downloads/WhatsApp Image 2025-08-21 at 14.01.47 - copia.jpeg
Traceback (most recent call last):
  File "C:\Users\Javier\Desktop\Proyectos\I2E\services\paddle_ocr.py", line 106, in _initialize_ocr
    self._ocr = PaddleOCR(**ocr_params)
  File "C:\Users\Javier\Desktop\Proyectos\I2E\.venv\lib\site-packages\paddleocr\_pipelines\ocr.py", line 163, in __init__
    super().__init__(**base_params)
  File "C:\Users\Javier\Desktop\Proyectos\I2E\.venv\lib\site-packages\paddleocr\_pipelines\base.py", line 63, in __init__
    self._common_args = parse_common_args(
  File "C:\Users\Javier\Desktop\Proyectos\I2E\.venv\lib\site-packages\paddleocr\_common_args.py", line 43, in parse_common_args
    raise ValueError(f"Unknown argument: {name}")
ValueError: Unknown argument: use_gpu

The above exception was the direct cause of the following exception:

Traceback (most recent call last):
  File "C:\Users\Javier\Desktop\Proyectos\I2E\services\paddle_ocr.py", line 144, in extract_text
    self._initialize_ocr()
  File "C:\Users\Javier\Desktop\Proyectos\I2E\services\paddle_ocr.py", line 114, in _initialize_ocr
    raise RuntimeError(f"Fallo en la inicialización de PaddleOCR: {str(e)}") from e
RuntimeError: Fallo en la inicialización de PaddleOCR: Unknown argument: use_gpu
2025-09-01 21:57:09 | ERROR    | ImageProcessor            | process_image       :122  | Error durante el procesamiento: Error en OCR: Fallo en la inicialización de PaddleOCR: Unknown argument: use_gpu
Traceback (most recent call last):
  File "C:\Users\Javier\Desktop\Proyectos\I2E\services\paddle_ocr.py", line 106, in _initialize_ocr
    self._ocr = PaddleOCR(**ocr_params)
  File "C:\Users\Javier\Desktop\Proyectos\I2E\.venv\lib\site-packages\paddleocr\_pipelines\ocr.py", line 163, in __init__
    super().__init__(**base_params)
  File "C:\Users\Javier\Desktop\Proyectos\I2E\.venv\lib\site-packages\paddleocr\_pipelines\base.py", line 63, in __init__
    self._common_args = parse_common_args(
  File "C:\Users\Javier\Desktop\Proyectos\I2E\.venv\lib\site-packages\paddleocr\_common_args.py", line 43, in parse_common_args
    raise ValueError(f"Unknown argument: {name}")
ValueError: Unknown argument: use_gpu

The above exception was the direct cause of the following exception:

Traceback (most recent call last):
  File "C:\Users\Javier\Desktop\Proyectos\I2E\services\paddle_ocr.py", line 144, in extract_text
    self._initialize_ocr()
  File "C:\Users\Javier\Desktop\Proyectos\I2E\services\paddle_ocr.py", line 114, in _initialize_ocr
    raise RuntimeError(f"Fallo en la inicialización de PaddleOCR: {str(e)}") from e
RuntimeError: Fallo en la inicialización de PaddleOCR: Unknown argument: use_gpu

The above exception was the direct cause of the following exception:

Traceback (most recent call last):
  File "C:\Users\Javier\Desktop\Proyectos\I2E\main.py", line 99, in process_image
    ocr_result = self._ocr_engine.extract_text(image_path)
  File "C:\Users\Javier\Desktop\Proyectos\I2E\services\paddle_ocr.py", line 172, in extract_text
    raise RuntimeError(f"Error en OCR: {str(e)}") from e
RuntimeError: Error en OCR: Fallo en la inicialización de PaddleOCR: Unknown argument: use_gpu
2025-09-01 21:57:11 | ERROR    | ImageToExcelApp           | on_processing_error :583  | Error en conversión: Error durante el procesamiento: Error en OCR: Fallo en la inicialización de PaddleOCR: Unknown argument: use_gpu
2025-09-01 21:57:15 | INFO     | ImageProcessor            | process_image       :79   | Iniciando procesamiento de imagen: C:/Users/Javier/Downloads/WhatsApp Image 2025-08-21 at 14.01.47 - copia.jpeg
2025-09-01 21:57:15 | INFO     | ImageToExcelApp           | on_processing_started:557  | Procesamiento iniciado
2025-09-01 21:57:15 | INFO     | ImageProcessor            | process_image       :98   | Ejecutando OCR en la imagen
2025-09-01 21:57:15 | INFO     | services.paddle_ocr       | _initialize_ocr     :78   | Inicializando motor PaddleOCR...
2025-09-01 21:57:15 | ERROR    | services.paddle_ocr       | _initialize_ocr     :113  | Error al inicializar motor PaddleOCR
Traceback (most recent call last):
  File "C:\Users\Javier\Desktop\Proyectos\I2E\services\paddle_ocr.py", line 106, in _initialize_ocr
    self._ocr = PaddleOCR(**ocr_params)
  File "C:\Users\Javier\Desktop\Proyectos\I2E\.venv\lib\site-packages\paddleocr\_pipelines\ocr.py", line 163, in __init__
    super().__init__(**base_params)
  File "C:\Users\Javier\Desktop\Proyectos\I2E\.venv\lib\site-packages\paddleocr\_pipelines\base.py", line 63, in __init__
    self._common_args = parse_common_args(
  File "C:\Users\Javier\Desktop\Proyectos\I2E\.venv\lib\site-packages\paddleocr\_common_args.py", line 43, in parse_common_args
    raise ValueError(f"Unknown argument: {name}")
ValueError: Unknown argument: use_gpu
2025-09-01 21:57:15 | ERROR    | services.paddle_ocr       | extract_text        :169  | Error en extracción de texto para imagen: C:/Users/Javier/Downloads/WhatsApp Image 2025-08-21 at 14.01.47 - copia.jpeg
Traceback (most recent call last):
  File "C:\Users\Javier\Desktop\Proyectos\I2E\services\paddle_ocr.py", line 106, in _initialize_ocr
    self._ocr = PaddleOCR(**ocr_params)
  File "C:\Users\Javier\Desktop\Proyectos\I2E\.venv\lib\site-packages\paddleocr\_pipelines\ocr.py", line 163, in __init__
    super().__init__(**base_params)
  File "C:\Users\Javier\Desktop\Proyectos\I2E\.venv\lib\site-packages\paddleocr\_pipelines\base.py", line 63, in __init__
    self._common_args = parse_common_args(
  File "C:\Users\Javier\Desktop\Proyectos\I2E\.venv\lib\site-packages\paddleocr\_common_args.py", line 43, in parse_common_args
    raise ValueError(f"Unknown argument: {name}")
ValueError: Unknown argument: use_gpu

The above exception was the direct cause of the following exception:

Traceback (most recent call last):
  File "C:\Users\Javier\Desktop\Proyectos\I2E\services\paddle_ocr.py", line 144, in extract_text
    self._initialize_ocr()
  File "C:\Users\Javier\Desktop\Proyectos\I2E\services\paddle_ocr.py", line 114, in _initialize_ocr
    raise RuntimeError(f"Fallo en la inicialización de PaddleOCR: {str(e)}") from e
RuntimeError: Fallo en la inicialización de PaddleOCR: Unknown argument: use_gpu
2025-09-01 21:57:15 | ERROR    | ImageProcessor            | process_image       :122  | Error durante el procesamiento: Error en OCR: Fallo en la inicialización de PaddleOCR: Unknown argument: use_gpu
Traceback (most recent call last):
  File "C:\Users\Javier\Desktop\Proyectos\I2E\services\paddle_ocr.py", line 106, in _initialize_ocr
    self._ocr = PaddleOCR(**ocr_params)
  File "C:\Users\Javier\Desktop\Proyectos\I2E\.venv\lib\site-packages\paddleocr\_pipelines\ocr.py", line 163, in __init__
    super().__init__(**base_params)
  File "C:\Users\Javier\Desktop\Proyectos\I2E\.venv\lib\site-packages\paddleocr\_pipelines\base.py", line 63, in __init__
    self._common_args = parse_common_args(
  File "C:\Users\Javier\Desktop\Proyectos\I2E\.venv\lib\site-packages\paddleocr\_common_args.py", line 43, in parse_common_args
    raise ValueError(f"Unknown argument: {name}")
ValueError: Unknown argument: use_gpu

The above exception was the direct cause of the following exception:

Traceback (most recent call last):
  File "C:\Users\Javier\Desktop\Proyectos\I2E\services\paddle_ocr.py", line 144, in extract_text
    self._initialize_ocr()
  File "C:\Users\Javier\Desktop\Proyectos\I2E\services\paddle_ocr.py", line 114, in _initialize_ocr
    raise RuntimeError(f"Fallo en la inicialización de PaddleOCR: {str(e)}") from e
RuntimeError: Fallo en la inicialización de PaddleOCR: Unknown argument: use_gpu

The above exception was the direct cause of the following exception:

Traceback (most recent call last):
  File "C:\Users\Javier\Desktop\Proyectos\I2E\main.py", line 99, in process_image
    ocr_result = self._ocr_engine.extract_text(image_path)
  File "C:\Users\Javier\Desktop\Proyectos\I2E\services\paddle_ocr.py", line 172, in extract_text
    raise RuntimeError(f"Error en OCR: {str(e)}") from e
RuntimeError: Error en OCR: Fallo en la inicialización de PaddleOCR: Unknown argument: use_gpu
2025-09-01 21:57:17 | ERROR    | ImageToExcelApp           | on_processing_error :583  | Error en conversión: Error durante el procesamiento: Error en OCR: Fallo en la inicialización de PaddleOCR: Unknown argument: use_gpu
2025-09-03 20:24:51 | INFO     | root                      | configure_logging   :164  | Sistema de logging configurado correctamente
2025-09-03 20:24:51 | INFO     | root                      | configure_logging   :165  | Nivel de logging: INFO
2025-09-03 20:24:51 | INFO     | root                      | configure_logging   :167  | Logs de archivo habilitados en: logs
2025-09-03 20:24:51 | INFO     | root                      | configure_logging   :169  | Logs de consola habilitados
2025-09-03 20:25:55 | INFO     | root                      | configure_logging   :164  | Sistema de logging configurado correctamente
2025-09-03 20:25:55 | INFO     | root                      | configure_logging   :165  | Nivel de logging: INFO
2025-09-03 20:25:55 | INFO     | root                      | configure_logging   :167  | Logs de archivo habilitados en: logs
2025-09-03 20:25:55 | INFO     | root                      | configure_logging   :169  | Logs de consola habilitados
2025-09-03 20:25:59 | INFO     | ImageToExcelApp           | select_image        :494  | Imagen seleccionada: C:/Users/Javier/Downloads/WhatsApp Image 2025-08-21 at 14.01.47 - copia.jpeg
2025-09-03 20:26:03 | INFO     | ImageToExcelApp           | select_output_directory:523  | Directorio de salida seleccionado: C:/Users/Javier/Downloads
2025-09-03 20:26:04 | INFO     | ImageProcessor            | process_image       :79   | Iniciando procesamiento de imagen: C:/Users/Javier/Downloads/WhatsApp Image 2025-08-21 at 14.01.47 - copia.jpeg
2025-09-03 20:26:04 | INFO     | ImageToExcelApp           | on_processing_started:557  | Procesamiento iniciado
2025-09-03 20:26:04 | INFO     | services.paddle_ocr       | __init__            :72   | PaddleOCREngine inicializado con configuración: language=es, use_angle_cls=True
2025-09-03 20:26:04 | INFO     | ImageProcessor            | process_image       :98   | Ejecutando OCR en la imagen
2025-09-03 20:26:04 | INFO     | services.paddle_ocr       | _initialize_ocr     :84   | Inicializando motor PaddleOCR...
2025-09-03 20:26:05 | INFO     | services.paddle_ocr       | _initialize_ocr     :123  | Usando configuración avanzada de PaddleOCR
2025-09-03 20:26:06 | INFO     | services.paddle_ocr       | _initialize_ocr     :134  | Motor PaddleOCR inicializado en 1.69 segundos
2025-09-03 20:26:06 | INFO     | services.paddle_ocr       | extract_text        :172  | Procesando imagen: C:/Users/Javier/Downloads/WhatsApp Image 2025-08-21 at 14.01.47 - copia.jpeg
2025-09-03 20:26:08 | INFO     | services.paddle_ocr       | extract_text        :188  | OCR completado en 2.67 segundos para imagen: C:/Users/Javier/Downloads/WhatsApp Image 2025-08-21 at 14.01.47 - copia.jpeg
2025-09-03 20:26:08 | INFO     | services.paddle_ocr       | _parse_ocr_result   :344  | Parseado OCR completado: 0 líneas extraídas de C:/Users/Javier/Downloads/WhatsApp Image 2025-08-21 at 14.01.47 - copia.jpeg
2025-09-03 20:26:08 | INFO     | ImageProcessor            | process_image       :103  | Convirtiendo resultado OCR a tabla
2025-09-03 20:26:08 | INFO     | TableParser               | __init__            :89   | TableParser inicializado con configuración: separadores=['\t', '  ', '|', ';', ','], min_column_width=3, max_columns=20
2025-09-03 20:26:08 | INFO     | TableParser               | parse_ocr_to_table  :130  | Iniciando parseo de 0 líneas OCR
2025-09-03 20:26:08 | INFO     | TableParser               | _filter_lines_by_confidence:207  | Filtrado por confianza: 0/0 líneas mantenidas
2025-09-03 20:26:08 | INFO     | TableParser               | parse_ocr_to_table  :153  | Parseo completado: 0 filas, 0 columnas, tiempo=0.001s, confianza=0.00
2025-09-03 20:26:08 | INFO     | services.parser           | ocr_to_table        :495  | Parseo OCR completado: 0 filas, 0 columnas, confianza=0.00
2025-09-03 20:26:08 | INFO     | ImageProcessor            | process_image       :108  | Exportando tabla a Excel
2025-09-03 20:26:08 | INFO     | ExcelExporter             | __init__            :86   | ExcelExporter inicializado con configuración: archivo=texto_extraido.xlsx, hoja=Texto Extraído, incluir_confianza=True
2025-09-03 20:26:08 | ERROR    | ExcelExporter             | export_table        :234  | Error durante la exportación a Excel
Traceback (most recent call last):
  File "C:\Users\Javier\Desktop\Proyectos\I2E\services\exporter.py", line 185, in export_table
    self._validate_export_params(table, output_dir)
  File "C:\Users\Javier\Desktop\Proyectos\I2E\services\exporter.py", line 254, in _validate_export_params
    raise ValueError("La tabla no puede estar vacía")
ValueError: La tabla no puede estar vacía
2025-09-03 20:26:08 | ERROR    | ImageProcessor            | process_image       :122  | Error durante el procesamiento: Error en exportación Excel: La tabla no puede estar vacía
Traceback (most recent call last):
  File "C:\Users\Javier\Desktop\Proyectos\I2E\services\exporter.py", line 185, in export_table
    self._validate_export_params(table, output_dir)
  File "C:\Users\Javier\Desktop\Proyectos\I2E\services\exporter.py", line 254, in _validate_export_params
    raise ValueError("La tabla no puede estar vacía")
ValueError: La tabla no puede estar vacía

The above exception was the direct cause of the following exception:

Traceback (most recent call last):
  File "C:\Users\Javier\Desktop\Proyectos\I2E\main.py", line 109, in process_image
    excel_path = export_table_to_excel(
  File "C:\Users\Javier\Desktop\Proyectos\I2E\services\exporter.py", line 532, in export_table_to_excel
    return exporter.export_table(table, ocr, output_dir, filename)
  File "C:\Users\Javier\Desktop\Proyectos\I2E\services\exporter.py", line 235, in export_table
    raise RuntimeError(f"Error en exportación Excel: {str(e)}") from e
RuntimeError: Error en exportación Excel: La tabla no puede estar vacía
2025-09-03 20:26:12 | ERROR    | ImageToExcelApp           | on_processing_error :583  | Error en conversión: Error durante el procesamiento: Error en exportación Excel: La tabla no puede estar vacía
2025-09-03 20:27:44 | INFO     | services.paddle_ocr       | clear_cache         :388  | Caché del motor OCR limpiado
2025-09-03 20:27:44 | INFO     | services.paddle_ocr       | shutdown            :399  | Motor OCR cerrado correctamente
